Workbook

Sheet TitlePage
A1: Dolby® Vision
A2: Consumer Decoder for Sink Devices
A3: Panel Attributes Measurement Form
A4: Version 4.3
A5: Date: Aug 7 2024
A7: © 2021 Dolby Laboratories. All rights reserved.
A8: Unauthorized use, sale, or duplication is prohibited.
A9: Nothing in this document constitutes a license
A10: to practice any particular standard.
A11: For information, contact:
A12: Dolby Laboratories, Inc.
A13: 1275 Market Street
... A16: http://www.dolby.com

Sheet Measurement data
B1: Cells in this sheet are automatically updated, enter measurement values in "Raw Data" sheet
B2: Sample
C3: 0 | D3: 10 | E3: 20 | F3: 30 | G3: 40 | H3: 50 | I3: 60 | J3: 70 | K3: 80 | L3: 90 | M3: 100
B4: x: CIE31 | C4: ='Raw Data'!E5 -> 0.25768157 | D4: ='Raw Data'!F5 -> 0.30233399 | E4: ='Raw Data'!G5 -> 0.3066711 | F4: ='Raw Data'!H5 -> 0.30727736 | G4: ='Raw Data'!I5 -> 0.30786201 | H4: ='Raw Data'!J5 -> 0.30822694 | I4: ='Raw Data'!K5 -> 0.30849409 | J4: ='Raw Data'!L5 -> 0.30900149 | ... M4: ='Raw Data'!O5 -> 0.31220603
B5: y: CIE31 | C5: ='Raw Data'!E6 -> 0.2614 | D5: ='Raw Data'!F6 -> 0.32486349 | E5: ='Raw Data'!G6 -> 0.33098091 | F5: ='Raw Data'!H6 -> 0.33182601 | G5: ='Raw Data'!I6 -> 0.33205059 | H5: ='Raw Data'!J6 -> 0.33216513 | I5: ='Raw Data'!K6 -> 0.33288427 | J5: ='Raw Data'!L6 -> 0.3334465 | ... M5: ='Raw Data'!O6 -> 0.33665801
B6: Y | C6: ='Raw Data'!E7 -> 0.075571 | D6: ='Raw Data'!F7 -> 0.758003 | E6: ='Raw Data'!G7 -> 3.278261 | F6: ='Raw Data'!H7 -> 7.682298 | G6: ='Raw Data'!I7 -> 13.756704 | H6: ='Raw Data'!J7 -> 23.279671 | I6: ='Raw Data'!K7 -> 36.223925 | J6: ='Raw Data'!L7 -> 52.682444 | ... M6: ='Raw Data'!O7 -> 120.10585
C8: W | D8: R | E8: G | F8: B | G8: Cy | H8: Mg | I8: Yw | J8: Bk
B9: x: CIE31 | C9: ='Raw Data'!O5 -> 0.31220603 | D9: ='Raw Data'!B5 -> 0.65153381 | E9: ='Raw Data'!C5 -> 0.30114822 | F9: ='Raw Data'!D5 -> 0.15273441 | J9: ='Raw Data'!E5 -> 0.25768157
B10: y: CIE31 | C10: ='Raw Data'!O6 -> 0.33665801 | D10: ='Raw Data'!B6 -> 0.32186303 | E10: ='Raw Data'!C6 -> 0.65552588 | F10: ='Raw Data'!D6 -> 0.063717058 | J10: ='Raw Data'!E6 -> 0.2614 | K10: contrast ratio
B11: Y | C11: ='Raw Data'!O7 -> 120.10585 | D11: ='Raw Data'!B7 -> 24.069394 | E11: ='Raw Data'!C7 -> 86.215165 | F11: ='Raw Data'!D7 -> 9.550172 | J11: ='Raw Data'!E7 -> 0.075571 | L11: =M6/C6 -> 1589.3113
B13: n | C13: =(C4-0.3366)/(C5-0.1735) -> -0.89782062 | D13: =(D4-0.3366)/(D5-0.1735) -> -0.22638225 | E13: =(E4-0.3366)/(E5-0.1735) -> -0.19004782 | F13: =(F4-0.3366)/(F5-0.1735) -> -0.18520417 | G13: =(G4-0.3366)/(G5-0.1735) -> -0.18125439 | H13: =(H4-0.3366)/(H5-0.1735) -> -0.17882351 | I13: =(I4-0.3366)/(I5-0.1735) -> -0.17634053 | J13: =(J4-0.3366)/(J5-0.1735) -> -0.17254838 | ... M13: =(M4-0.3366)/(M5-0.1735) -> -0.14951134
B14: CCT | C14: =-949.86315+6253.80338*EXP(-C13/0.92159)+28.70599*EXP(-C13/0.20039)+0.00004*EXP(-C13/0.07125) -> 18162.56 | D14: =-949.86315+6253.80338*EXP(-D13/0.92159)+28.70599*EXP(-D13/0.20039)+0.00004*EXP(-D13/0.07125) -> 7134.1085 | E14: =-949.86315+6253.80338*EXP(-E13/0.92159)+28.70599*EXP(-E13/0.20039)+0.00004*EXP(-E13/0.07125) -> 6810.2944 | F14: =-949.86315+6253.80338*EXP(-F13/0.92159)+28.70599*EXP(-F13/0.20039)+0.00004*EXP(-F13/0.07125) -> 6768.2346 | G14: =-949.86315+6253.80338*EXP(-G13/0.92159)+28.70599*EXP(-G13/0.20039)+0.00004*EXP(-G13/0.07125) -> 6734.1245 | H14: =-949.86315+6253.80338*EXP(-H13/0.92159)+28.70599*EXP(-H13/0.20039)+0.00004*EXP(-H13/0.07125) -> 6713.2147 | I14: =-949.86315+6253.80338*EXP(-I13/0.92159)+28.70599*EXP(-I13/0.20039)+0.00004*EXP(-I13/0.07125) -> 6691.9221 | J14: =-949.86315+6253.80338*EXP(-J13/0.92159)+28.70599*EXP(-J13/0.20039)+0.00004*EXP(-J13/0.07125) -> 6659.5291 | ... M14: =-949.86315+6253.80338*EXP(-M13/0.92159)+28.70599*EXP(-M13/0.20039)+0.00004*EXP(-M13/0.07125) -> 6465.9759 | N14: ="White point: "&TEXT(M14,"00 K") -> White point: 6466 K
B15: Reference | C15: =((C3/100)^$B$16)*($M$6-$C$6)+$C$6 -> 0.075571 | D15: =((D3/100)^$B$16)*($M$6-$C$6)+$C$6 -> 0.68585569 | E15: =((E3/100)^$B$16)*($M$6-$C$6)+$C$6 -> 3.0679909 | F15: =((F3/100)^$B$16)*($M$6-$C$6)+$C$6 -> 7.6601823 | G15: =((G3/100)^$B$16)*($M$6-$C$6)+$C$6 -> 14.748357 | H15: =((H3/100)^$B$16)*($M$6-$C$6)+$C$6 -> 24.55497 | I15: =((I3/100)^$B$16)*($M$6-$C$6)+$C$6 -> 37.265332 | J15: =((J3/100)^$B$16)*($M$6-$C$6)+$C$6 -> 53.03986 | ... M15: =((M3/100)^$B$16)*($M$6-$C$6)+$C$6 -> 120.10585 | N15: ="Reference gamma = "&TEXT(B16,"0.00") -> Reference gamma = 2.29
B16: =AVERAGE(D16:L16) -> 2.2937583 | D16: =(LOG10(D6-$C$6)-LOG10($M6-$C6))/LOG10(D3/100) -> 2.2452314 | E16: =(LOG10(E6-$C$6)-LOG10($M6-$C6))/LOG10(E3/100) -> 2.2515643 | F16: =(LOG10(F6-$C$6)-LOG10($M6-$C6))/LOG10(F3/100) -> 2.29134 | G16: =(LOG10(G6-$C$6)-LOG10($M6-$C6))/LOG10(G3/100) -> 2.370128 | H16: =(LOG10(H6-$C$6)-LOG10($M6-$C6))/LOG10(H3/100) -> 2.3709467 | I16: =(LOG10(I6-$C$6)-LOG10($M6-$C6))/LOG10(I3/100) -> 2.3493586 | J16: =(LOG10(J6-$C$6)-LOG10($M6-$C6))/LOG10(J3/100) -> 2.3127423 | K16: =(LOG10(K6-$C$6)-LOG10($M6-$C6))/LOG10(K3/100) -> 2.3087153 | L16: =(LOG10(L6-$C$6)-LOG10($M6-$C6))/LOG10(L3/100) -> 2.1437983 | M16: 1
B18: Area 31 | C18: =0.5*ABS(E9*D10-D9*E10+D9*F10-F9*D10+F9*E10-E9*F10) -> 0.12844073
B19: % 2020 | C19: =C18/C24 -> 0.60623425 | N19: ="This panel: "&TEXT(C19,"00.0%")&","&TEXT(C22,"00.0%")&","&TEXT(C20,"00.0%")&","&TEXT(C21,"00.0%") -> This panel: 60.6%,81.2%,84.5%,114.6%
B20: % P3 | C20: =C18/C25 -> 0.84500479
B21: % 709 | C21: =C18/C26 -> 1.1462805
B22: % NTSC | C22: =C18/C27 -> 0.8118883
B24: Area2020 | C24: 0.2118665
B25: AreaP3 | C25: 0.152
B26: Area709 | C26: 0.11205
B27: AreaNTSC | C27: 0.1582
C29: W | D29: R | E29: G | F29: B | G29: Cy | H29: Mg | I29: Yw | J29: Bk
B30: u:CIE1976 | C30: =4*C9/(-2*C9+12*C10+3) -> 0.19465781 | D30: =4*D9/(-2*D9+12*D10+3) -> 0.46878933 | E30: =4*E9/(-2*E9+12*E10+3) -> 0.1173608 | F30: =4*F9/(-2*F9+12*F10+3) -> 0.17661568 | G30: =4*G9/(-2*G9+12*G10+3) -> 0 | H30: =4*H9/(-2*H9+12*H10+3) -> 0 | I30: =4*I9/(-2*I9+12*I10+3) -> 0 | J30: =4*J9/(-2*J9+12*J10+3) -> 0.18335638
B31: v:CIE1976 | C31: =9*C10/(-2*C9+12*C10+3) -> 0.47228269 | D31: =9*D10/(-2*D9+12*D10+3) -> 0.52106796 | E31: =9*E10/(-2*E9+12*E10+3) -> 0.57479782 | F31: =9*F10/(-2*F9+12*F10+3) -> 0.16577941 | G31: =9*G10/(-2*G9+12*G10+3) -> 0 | H31: =9*H10/(-2*H9+12*H10+3) -> 0 | I31: =9*I10/(-2*I9+12*I10+3) -> 0 | J31: =9*J10/(-2*J9+12*J10+3) -> 0.4185051
B34: Area 76 | C34: =0.5*ABS(E30*D31-D30*E31+D30*F31-F30*D31+F30*E31-E30*F31) -> 0.07027849
B35: % 2020 | C35: =C34/C40 -> 0.62848182 | N35: ="This panel: "&TEXT(C35,"00.0%")&","&TEXT(C38,"00.0%")&","&TEXT(C36,"00.0%")&","&TEXT(C37,"00.0%") -> This panel: 62.8%,94.4%,86.3%,108.3%
B36: % P3 | C36: =C34/C41 -> 0.86252205
B37: % 709 | C37: =C34/C42 -> 1.08301
B38: % NTSC | C38: =C34/C43 -> 0.94427676
B40: Area2020 | C40: 0.11182263
B41: AreaP3 | C41: 0.081480224
B42: Area709 | C42: 0.064891818
B43: AreaNTSC | C43: 0.074425733
B46: Tmax = | C46: =C11 -> 120.10585
B47: Tmin = | C47: =C6 -> 0.075571
B48: TPrimaries = | C48: =D9 -> 0.65153381 | D48: =D10 -> 0.32186303 | E48: =E9 -> 0.30114822 | F48: =E10 -> 0.65552588 | G48: =F9 -> 0.15273441 | H48: =F10 -> 0.063717058 | I48: =C9 -> 0.31220603 | J48: =C10 -> 0.33665801
B49: Tgamma = | C49: =TEXT(B16,"0.00") -> 2.29

Sheet Plots

Sheet Raw Data
B1: R | C1: G | D1: B | E1: 0 | F1: 10 | G1: 20 | H1: 30 | I1: 40 | J1: 50 | K1: 60 | L1: 70 | M1: 80 | N1: 90 | O1: 100
A2: X | B2: 48.722663 | C2: 39.607198 | D2: 22.892455 | E2: 0.074496 | F2: 0.705435 | G2: 3.03748 | H2: 7.113958 | I2: 12.754582 | J2: 21.601972 | K2: 33.569826 | L2: 48.820287 | M2: 66.584977 | N2: 88.902962 | O2: 111.38238
A3: Y | B3: 24.069394 | C3: 86.215165 | D3: 9.550172 | E3: 0.075571 | F3: 0.758003 | G3: 3.278261 | H3: 7.682298 | I3: 13.756704 | J3: 23.279671 | K3: 36.223925 | L3: 52.682444 | M3: 71.781187 | N3: 95.838181 | O3: 120.10585
A4: Z | B4: 1.989424 | C4: 5.698249 | D4: 117.44144 | E4: 0.139034 | F4: 0.869859 | G4: 3.588942 | H4: 8.355329 | I4: 14.918256 | J4: 25.202989 | K4: 39.024624 | L4: 56.490963 | M4: 76.504021 | N4: 101.06833 | O4: 125.27099
A5: x | B5: =B2/SUM(B2:B4) -> 0.65153381 | C5: =C2/SUM(C2:C4) -> 0.30114822 | D5: =D2/SUM(D2:D4) -> 0.15273441 | E5: =IF(SUM(E2:E4)=0,F5,E2/SUM(E2:E4)) -> 0.25768157 | F5: =IF(SUM(F2:F4)=0,G5,F2/SUM(F2:F4)) -> 0.30233399 | G5: =G2/SUM(G2:G4) -> 0.3066711 | H5: =H2/SUM(H2:H4) -> 0.30727736 | I5: =I2/SUM(I2:I4) -> 0.30786201 | J5: =J2/SUM(J2:J4) -> 0.30822694 | K5: =K2/SUM(K2:K4) -> 0.30849409 | L5: =L2/SUM(L2:L4) -> 0.30900149 | M5: =M2/SUM(M2:M4) -> 0.30988467 | N5: =N2/SUM(N2:N4) -> 0.31105674 | O5: =O2/SUM(O2:O4) -> 0.31220603
A6: y | B6: =B3/SUM(B2:B4) -> 0.32186303 | C6: =C3/SUM(C2:C4) -> 0.65552588 | D6: =D3/SUM(D2:D4) -> 0.063717058 | E6: =IF(SUM(E2:E4)=0,F6,E3/SUM(E2:E4)) -> 0.2614 | F6: =IF(SUM(F2:F4)=0,G6,F3/SUM(F2:F4)) -> 0.32486349 | G6: =G3/SUM(G2:G4) -> 0.33098091 | H6: =H3/SUM(H2:H4) -> 0.33182601 | I6: =I3/SUM(I2:I4) -> 0.33205059 | J6: =J3/SUM(J2:J4) -> 0.33216513 | K6: =K3/SUM(K2:K4) -> 0.33288427 | L6: =L3/SUM(L2:L4) -> 0.3334465 | M6: =M3/SUM(M2:M4) -> 0.33406769 | N6: =N3/SUM(N2:N4) -> 0.33532193 | O6: =O3/SUM(O2:O4) -> 0.33665801
A7: Y | B7: =B3 -> 24.069394 | C7: =C3 -> 86.215165 | D7: =D3 -> 9.550172 | E7: =E3 -> 0.075571 | F7: =F3 -> 0.758003 | G7: =G3 -> 3.278261 | H7: =H3 -> 7.682298 | I7: =I3 -> 13.756704 | ... O7: =O3 -> 120.10585

Sheet References
A1: Planckian Locus | E1: Spectrum Locus
A2: CCT | B2: x | C2: y | E2: x | F2: y
A3: 1000 | B3: 0.6499 | C3: 0.3474 | E3: 0.17411223 | F3: 0.004963726 | I3: sRGB
A4: 2000 | B4: 0.5267 | C4: 0.4173 | E4: 0.17407258 | F4: 0.0049725848 | K4: x | L4: y
A5: 3000 | B5: 0.4388 | C5: 0.4095 | E5: 0.17403628 | F5: 0.0049859267 | I5: R | K5: 0.64 | L5: 0.33
A6: 4000 | B6: 0.3827 | C6: 0.382 | E6: 0.17397193 | F6: 0.0049640688 | I6: G | K6: 0.3 | L6: 0.6
A7: 5000 | B7: 0.3473 | C7: 0.3561 | E7: 0.17388904 | F7: 0.0049260401 | I7: B | K7: 0.15 | L7: 0.06
A8: 6000 | B8: 0.3242 | C8: 0.3355 | E8: 0.17380077 | F8: 0.0049154119 | I8: R | K8: 0.64 | L8: 0.33
A9: 7000 | B9: 0.3083 | C9: 0.3195 | E9: 0.17370535 | F9: 0.0049370984
A10: 8000 | B10: 0.297 | C10: 0.3071 | E10: 0.17360602 | F10: 0.0049398953
A11: 9000 | B11: 0.2887 | C11: 0.2975 | E11: 0.17351445 | F11: 0.0048954526
A12: 10000 | B12: 0.2824 | C12: 0.2898 | E12: 0.17342367 | F12: 0.0048363121 | I12: AdobeRGB
A13: 11000 | B13: 0.2774 | C13: 0.2836 | E13: 0.17333687 | F13: 0.0047967434 | K13: x | L13: y
A14: 12000 | B14: 0.2734 | C14: 0.2785 | E14: 0.17323792 | F14: 0.0047788879 | I14: R | K14: 0.64 | L14: 0.33
A15: 13000 | B15: 0.2702 | C15: 0.2742 | E15: 0.17310101 | F15: 0.0047740332 | I15: G | K15: 0.21 | L15: 0.71
A16: 14000 | B16: 0.2675 | C16: 0.2707 | E16: 0.17293426 | F16: 0.0047811472 | I16: B | K16: 0.15 | L16: 0.06
A17: 15000 | B17: 0.2653 | C17: 0.2676 | E17: 0.17275115 | F17: 0.0047987621 | I17: R | K17: 0.64 | L17: 0.33
A18: 16000 | B18: 0.2634 | C18: 0.265 | E18: 0.17257655 | F18: 0.0047993019
A19: 17000 | B19: 0.2618 | C19: 0.2627 | E19: 0.1723956 | F19: 0.0047961186
A20: 18000 | B20: 0.2604 | C20: 0.2607 | E20: 0.17219236 | F20: 0.0048148852
E21: 0.17198245 | F21: 0.0048550102 | I21: P3
B22: D65 | E22: 0.17174121 | F22: 0.0049393325 | K22: x | L22: y
B23: 0.3127 | C23: 0.329 | E23: 0.17140743 | F23: 0.005102171 | I23: R | K23: 0.68 | L23: 0.32
E24: 0.17099257 | F24: 0.0053339078 | I24: G | K24: 0.265 | L24: 0.69
E25: 0.17054066 | F25: 0.0056209699 | I25: B | K25: 0.15 | L25: 0.06
E26: 0.17005016 | F26: 0.0059738951 | I26: R | K26: 0.68 | L26: 0.32
E27: 0.1695046 | F27: 0.0063980369
E28: 0.16887752 | F28: 0.0069002439
E29: 0.16814615 | F29: 0.0074906797 | I29: 2020
E30: 0.16732833 | F30: 0.0081753997 | K30: x | L30: y
E31: 0.16644633 | F31: 0.0089644004 | I31: R | K31: 0.708 | L31: 0.292
E32: 0.1654833 | F32: 0.009864681 | I32: G | K32: 0.17 | L32: 0.797
E33: 0.16441176 | F33: 0.010857558 | I33: B | K33: 0.131 | L33: 0.046
E34: 0.1632099 | F34: 0.011937386 | I34: R | K34: 0.708 | L34: 0.292
E35: 0.16185144 | F35: 0.013137307
E36: 0.1603096 | F36: 0.014491378
E37: 0.15857311 | F37: 0.016015156 | I37: NTSC 1953
E38: 0.15664166 | F38: 0.017704887 | K38: x | L38: y
E39: 0.15452461 | F39: 0.019555698 | I39: R | K39: 0.67 | L39: 0.33
E40: 0.15221924 | F40: 0.021611711 | I40: G | K40: 0.21 | L40: 0.71
...

Sheet Reference1976
A1: Planckian Locus | E1: Spectrum Locus
A2: CCT | B2: x | C2: y | E2: x | F2: y
A3: 1000 | B3: =4*References!B3/(-2*References!B3+12*References!C3+3) -> 0.44293747 | C3: =9*References!C3/(-2*References!B3+12*References!C3+3) -> 0.5327313 | E3: =4*References!E3/(-2*References!E3+12*References!F3+3) -> 0.25686519 | F3: =9*References!F3/(-2*References!E3+12*References!F3+3) -> 0.01647655 | I3: sRGB
A4: 2000 | B4: =4*References!B4/(-2*References!B4+12*References!C4+3) -> 0.30295361 | C4: =9*References!C4/(-2*References!B4+12*References!C4+3) -> 0.54006212 | E4: =4*References!E4/(-2*References!E4+12*References!F4+3) -> 0.25678912 | F4: =9*References!F4/(-2*References!E4+12*References!F4+3) -> 0.016504826 | K4: u | L4: v
A5: 3000 | B5: =4*References!B5/(-2*References!B5+12*References!C5+3) -> 0.24944574 | C5: =9*References!C5/(-2*References!B5+12*References!C5+3) -> 0.52377636 | E5: =4*References!E5/(-2*References!E5+12*References!F5+3) -> 0.25671353 | F5: =9*References!F5/(-2*References!E5+12*References!F5+3) -> 0.01654769 | I5: R | K5: =4*References!K5/(-2*References!K5+12*References!L5+3) -> 0.45070423 | L5: =9*References!L5/(-2*References!K5+12*References!L5+3) -> 0.52288732
A6: 4000 | B6: =4*References!B6/(-2*References!B6+12*References!C6+3) -> 0.22450356 | C6: =9*References!C6/(-2*References!B6+12*References!C6+3) -> 0.50420908 | E6: =4*References!E6/(-2*References!E6+12*References!F6+3) -> 0.25663126 | F6: =9*References!F6/(-2*References!E6+12*References!F6+3) -> 0.016475958 | I6: G | K6: =4*References!K6/(-2*References!K6+12*References!L6+3) -> 0.125 | L6: =9*References!L6/(-2*References!K6+12*References!L6+3) -> 0.5625
A7: 5000 | B7: =4*References!B7/(-2*References!B7+12*References!C7+3) -> 0.21116955 | C7: =9*References!C7/(-2*References!B7+12*References!C7+3) -> 0.48717052 | E7: =4*References!E7/(-2*References!E7+12*References!F7+3) -> 0.25653647 | F7: =9*References!F7/(-2*References!E7+12*References!F7+3) -> 0.016351491 | I7: B | K7: =4*References!K7/(-2*References!K7+12*References!L7+3) -> 0.1754386 | L7: =9*References!L7/(-2*References!K7+12*References!L7+3) -> 0.15789474
A8: 6000 | B8: =4*References!B8/(-2*References!B8+12*References!C8+3) -> 0.20333668 | C8: =9*References!C8/(-2*References!B8+12*References!C8+3) -> 0.47345396 | E8: =4*References!E8/(-2*References!E8+12*References!F8+3) -> 0.25640162 | F8: =9*References!F8/(-2*References!E8+12*References!F8+3) -> 0.016315917 | I8: R | K8: =4*References!K8/(-2*References!K8+12*References!L8+3) -> 0.45070423 | L8: =9*References!L8/(-2*References!K8+12*References!L8+3) -> 0.52288732
A9: 7000 | B9: =4*References!B9/(-2*References!B9+12*References!C9+3) -> 0.19834658 | C9: =9*References!C9/(-2*References!B9+12*References!C9+3) -> 0.46249236 | E9: =4*References!E9/(-2*References!E9+12*References!F9+3) -> 0.25621822 | F9: =9*References!F9/(-2*References!E9+12*References!F9+3) -> 0.016385176
A10: 8000 | B10: =4*References!B10/(-2*References!B10+12*References!C10+3) -> 0.19503546 | C10: =9*References!C10/(-2*References!B10+12*References!C10+3) -> 0.45375296 | E10: =4*References!E10/(-2*References!E10+12*References!F10+3) -> 0.25604978 | F10: =9*References!F10/(-2*References!E10+12*References!F10+3) -> 0.016393055
A11: 9000 | B11: =4*References!B11/(-2*References!B11+12*References!C11+3) -> 0.19270434 | C11: =9*References!C11/(-2*References!B11+12*References!C11+3) -> 0.44680105 | E11: =4*References!E11/(-2*References!E11+12*References!F11+3) -> 0.25594777 | F11: =9*References!F11/(-2*References!E11+12*References!F11+3) -> 0.016247669
A12: 10000 | B12: =4*References!B12/(-2*References!B12+12*References!C12+3) -> 0.19104316 | C12: =9*References!C12/(-2*References!B12+12*References!C12+3) -> 0.44111081 | E12: =4*References!E12/(-2*References!E12+12*References!F12+3) -> 0.25586369 | F12: =9*References!F12/(-2*References!E12+12*References!F12+3) -> 0.016054513 | I12: AdobeRGB
A13: 11000 | B13: =4*References!B13/(-2*References!B13+12*References!C13+3) -> 0.1897271 | C13: =9*References!C13/(-2*References!B13+12*References!C13+3) -> 0.43642706 | E13: =4*References!E13/(-2*References!E13+12*References!F13+3) -> 0.25576404 | F13: =9*References!F13/(-2*References!E13+12*References!F13+3) -> 0.015924931 | K13: u | L13: v
A14: 12000 | B14: =4*References!B14/(-2*References!B14+12*References!C14+3) -> 0.1887079 | C14: =9*References!C14/(-2*References!B14+12*References!C14+3) -> 0.43251311 | E14: =4*References!E14/(-2*References!E14+12*References!F14+3) -> 0.25561959 | F14: =9*References!F14/(-2*References!E14+12*References!F14+3) -> 0.015865747 | I14: R | K14: =4*References!K14/(-2*References!K14+12*References!L14+3) -> 0.45070423 | L14: =9*References!L14/(-2*References!K14+12*References!L14+3) -> 0.52288732
A15: 13000 | B15: =4*References!B15/(-2*References!B15+12*References!C15+3) -> 0.18796522 | C15: =9*References!C15/(-2*References!B15+12*References!C15+3) -> 0.42918261 | E15: =4*References!E15/(-2*References!E15+12*References!F15+3) -> 0.25539727 | F15: =9*References!F15/(-2*References!E15+12*References!F15+3) -> 0.015848369 | I15: G | K15: =4*References!K15/(-2*References!K15+12*References!L15+3) -> 0.075675676 | L15: =9*References!L15/(-2*References!K15+12*References!L15+3) -> 0.57567568
A16: 14000 | B16: =4*References!B16/(-2*References!B16+12*References!C16+3) -> 0.18727903 | C16: =9*References!C16/(-2*References!B16+12*References!C16+3) -> 0.42641859 | E16: =4*References!E16/(-2*References!E16+12*References!F16+3) -> 0.25511182 | F16: =9*References!F16/(-2*References!E16+12*References!F16+3) -> 0.015869534 | I16: B | K16: =4*References!K16/(-2*References!K16+12*References!L16+3) -> 0.1754386 | L16: =9*References!L16/(-2*References!K16+12*References!L16+3) -> 0.15789474
A17: 15000 | B17: =4*References!B17/(-2*References!B17+12*References!C17+3) -> 0.18681125 | C17: =9*References!C17/(-2*References!B17+12*References!C17+3) -> 0.4239693 | E17: =4*References!E17/(-2*References!E17+12*References!F17+3) -> 0.25478743 | F17: =9*References!F17/(-2*References!E17+12*References!F17+3) -> 0.015924609 | I17: R | K17: =4*References!K17/(-2*References!K17+12*References!L17+3) -> 0.45070423 | L17: =9*References!L17/(-2*References!K17+12*References!L17+3) -> 0.52288732
A18: 16000 | B18: =4*References!B18/(-2*References!B18+12*References!C18+3) -> 0.18637232 | C18: =9*References!C18/(-2*References!B18+12*References!C18+3) -> 0.42188495 | E18: =4*References!E18/(-2*References!E18+12*References!F18+3) -> 0.25449653 | F18: =9*References!F18/(-2*References!E18+12*References!F18+3) -> 0.015924312
A19: 17000 | B19: =4*References!B19/(-2*References!B19+12*References!C19+3) -> 0.18604321 | C19: =9*References!C19/(-2*References!B19+12*References!C19+3) -> 0.42003624 | E19: =4*References!E19/(-2*References!E19+12*References!F19+3) -> 0.25419936 | F19: =9*References!F19/(-2*References!E19+12*References!F19+3) -> 0.015911851
A20: 18000 | B20: =4*References!B20/(-2*References!B20+12*References!C20+3) -> 0.18574791 | C20: =9*References!C20/(-2*References!B20+12*References!C20+3) -> 0.41841429 | E20: =4*References!E20/(-2*References!E20+12*References!F20+3) -> 0.25384057 | F20: =9*References!F20/(-2*References!E20+12*References!F20+3) -> 0.015970393
E21: =4*References!E21/(-2*References!E21+12*References!F21+3) -> 0.25344693 | F21: =9*References!F21/(-2*References!E21+12*References!F21+3) -> 0.016098135 | I21: P3
B22: D65 | E22: =4*References!E22/(-2*References!E22+12*References!F22+3) -> 0.25295217 | F22: =9*References!F22/(-2*References!E22+12*References!F22+3) -> 0.016368717 | K22: u | L22: v
B23: =4*References!B23/(-2*References!B23+12*References!C23+3) -> 0.19783001 | C23: =9*References!C23/(-2*References!B23+12*References!C23+3) -> 0.46831999 | E23: =4*References!E23/(-2*References!E23+12*References!F23+3) -> 0.25221708 | F23: =9*References!F23/(-2*References!E23+12*References!F23+3) -> 0.01689205 | I23: R | K23: =4*References!K23/(-2*References!K23+12*References!L23+3) -> 0.49635036 | L23: =9*References!L23/(-2*References!K23+12*References!L23+3) -> 0.52554745
E24: =4*References!E24/(-2*References!E24+12*References!F24+3) -> 0.2512729 | F24: =9*References!F24/(-2*References!E24+12*References!F24+3) -> 0.017635851 | I24: G | K24: =4*References!K24/(-2*References!K24+12*References!L24+3) -> 0.098604651 | L24: =9*References!L24/(-2*References!K24+12*References!L24+3) -> 0.57767442
E25: =4*References!E25/(-2*References!E25+12*References!F25+3) -> 0.25020909 | F25: =9*References!F25/(-2*References!E25+12*References!F25+3) -> 0.01855534 | I25: B | K25: =4*References!K25/(-2*References!K25+12*References!L25+3) -> 0.1754386 | L25: =9*References!L25/(-2*References!K25+12*References!L25+3) -> 0.15789474
E26: =4*References!E26/(-2*References!E26+12*References!F26+3) -> 0.24901304 | F26: =9*References!F26/(-2*References!E26+12*References!F26+3) -> 0.019682722 | I26: R | K26: =4*References!K26/(-2*References!K26+12*References!L26+3) -> 0.49635036 | L26: =9*References!L26/(-2*References!K26+12*References!L26+3) -> 0.52554745
E27: =4*References!E27/(-2*References!E27+12*References!F27+3) -> 0.24765378 | F27: =9*References!F27/(-2*References!E27+12*References!F27+3) -> 0.021032589
E28: =4*References!E28/(-2*References!E28+12*References!F28+3) -> 0.24608317 | F28: =9*References!F28/(-2*References!E28+12*References!F28+3) -> 0.022623356
E29: =4*References!E29/(-2*References!E29+12*References!F29+3) -> 0.24425682 | F29: =9*References!F29/(-2*References!E29+12*References!F29+3) -> 0.024482938 | I29: 2020
E30: =4*References!E30/(-2*References!E30+12*References!F30+3) -> 0.24220223 | F30: =9*References!F30/(-2*References!E30+12*References!F30+3) -> 0.026625648 | K30: u | L30: v
E31: =4*References!E31/(-2*References!E31+12*References!F31+3) -> 0.23995029 | F31: =9*References!F31/(-2*References!E31+12*References!F31+3) -> 0.029077083 | I31: R | K31: =4*References!K31/(-2*References!K31+12*References!L31+3) -> 0.55660377 | L31: =9*References!L31/(-2*References!K31+12*References!L31+3) -> 0.51650943
E32: =4*References!E32/(-2*References!E32+12*References!F32+3) -> 0.23747253 | F32: =9*References!F32/(-2*References!E32+12*References!F32+3) -> 0.031851124 | I32: G | K32: =4*References!K32/(-2*References!K32+12*References!L32+3) -> 0.055628272 | L32: =9*References!L32/(-2*References!K32+12*References!L32+3) -> 0.58679647
E33: =4*References!E33/(-2*References!E33+12*References!F33+3) -> 0.23475093 | F33: =9*References!F33/(-2*References!E33+12*References!F33+3) -> 0.034881017 | I33: B | K33: =4*References!K33/(-2*References!K33+12*References!L33+3) -> 0.15927052 | L33: =9*References!L33/(-2*References!K33+12*References!L33+3) -> 0.12583587
E34: =4*References!E34/(-2*References!E34+12*References!F34+3) -> 0.23176402 | F34: =9*References!F34/(-2*References!E34+12*References!F34+3) -> 0.03814093 | I34: R | K34: =4*References!K34/(-2*References!K34+12*References!L34+3) -> 0.55660377 | L34: =9*References!L34/(-2*References!K34+12*References!L34+3) -> 0.51650943
E35: =4*References!E35/(-2*References!E35+12*References!F35+3) -> 0.22844685 | F35: =9*References!F35/(-2*References!E35+12*References!F35+3) -> 0.041721266
E36: =4*References!E36/(-2*References!E36+12*References!F36+3) -> 0.22473749 | F36: =9*References!F36/(-2*References!E36+12*References!F36+3) -> 0.045709683
E37: =4*References!E37/(-2*References!E37+12*References!F37+3) -> 0.22062072 | F37: =9*References!F37/(-2*References!E37+12*References!F37+3) -> 0.050133781 | I37: NTSC 1953
E38: =4*References!E38/(-2*References!E38+12*References!F38+3) -> 0.21611892 | F38: =9*References!F38/(-2*References!E38+12*References!F38+3) -> 0.054961832 | K38: u | L38: v
E39: =4*References!E39/(-2*References!E39+12*References!F39+3) -> 0.21127099 | F39: =9*References!F39/(-2*References!E39+12*References!F39+3) -> 0.060158644 | I39: R | K39: =4*References!K39/(-2*References!K39+12*References!L39+3) -> 0.47686833 | L39: =9*References!L39/(-2*References!K39+12*References!L39+3) -> 0.52846975
E40: =4*References!E40/(-2*References!E40+12*References!F40+3) -> 0.20605656 | F40: =9*References!F40/(-2*References!E40+12*References!F40+3) -> 0.065824652 | I40: G | K40: =4*References!K40/(-2*References!K40+12*References!L40+3) -> 0.075675676 | L40: =9*References!L40/(-2*References!K40+12*References!L40+3) -> 0.57567568
...
